{
 "cells": [
  {
   "cell_type": "code",
   "execution_count": 2,
   "metadata": {},
   "outputs": [
    {
     "data": {
      "text/plain": [
       "7"
      ]
     },
     "execution_count": 2,
     "metadata": {},
     "output_type": "execute_result"
    }
   ],
   "source": [
    "eval('2 * 3 + 1')"
   ]
  },
  {
   "cell_type": "code",
   "execution_count": 3,
   "metadata": {},
   "outputs": [
    {
     "ename": "NameError",
     "evalue": "name 'hello' is not defined",
     "output_type": "error",
     "traceback": [
      "\u001b[1;31m---------------------------------------------------------------------------\u001b[0m",
      "\u001b[1;31mNameError\u001b[0m                                 Traceback (most recent call last)",
      "Cell \u001b[1;32mIn[3], line 1\u001b[0m\n\u001b[1;32m----> 1\u001b[0m \u001b[39meval\u001b[39;49m(\u001b[39m'\u001b[39;49m\u001b[39mhello\u001b[39;49m\u001b[39m'\u001b[39;49m)\n",
      "File \u001b[1;32m<string>:1\u001b[0m\n",
      "\u001b[1;31mNameError\u001b[0m: name 'hello' is not defined"
     ]
    }
   ],
   "source": [
    "eval('hello')\n",
    "\n",
    "#Resposta 1: Por se tratar de uma expressão que não é reconhecido no interpretador python, o compilador apresenta a mensagem de erro.\n"
   ]
  },
  {
   "cell_type": "code",
   "execution_count": 4,
   "metadata": {},
   "outputs": [
    {
     "data": {
      "text/plain": [
       "'hellonotworld!'"
      ]
     },
     "execution_count": 4,
     "metadata": {},
     "output_type": "execute_result"
    }
   ],
   "source": [
    "eval(\"'hello' + 'not'+ 'world!'\")"
   ]
  },
  {
   "cell_type": "code",
   "execution_count": 5,
   "metadata": {},
   "outputs": [
    {
     "data": {
      "text/plain": [
       "2"
      ]
     },
     "execution_count": 5,
     "metadata": {},
     "output_type": "execute_result"
    }
   ],
   "source": [
    "eval(\"'ASCII'.count('I')\")"
   ]
  },
  {
   "cell_type": "code",
   "execution_count": 6,
   "metadata": {},
   "outputs": [
    {
     "ename": "SyntaxError",
     "evalue": "invalid syntax (<string>, line 1)",
     "output_type": "error",
     "traceback": [
      "Traceback \u001b[1;36m(most recent call last)\u001b[0m:\n",
      "\u001b[0m  File \u001b[0;32m~\\AppData\\Roaming\\Python\\Python310\\site-packages\\IPython\\core\\interactiveshell.py:3505\u001b[0m in \u001b[0;35mrun_code\u001b[0m\n    exec(code_obj, self.user_global_ns, self.user_ns)\u001b[0m\n",
      "\u001b[1;36m  Cell \u001b[1;32mIn[6], line 1\u001b[1;36m\n\u001b[1;33m    eval('x = 5')\u001b[1;36m\n",
      "\u001b[1;36m  File \u001b[1;32m<string>:1\u001b[1;36m\u001b[0m\n\u001b[1;33m    x = 5\u001b[0m\n\u001b[1;37m      ^\u001b[0m\n\u001b[1;31mSyntaxError\u001b[0m\u001b[1;31m:\u001b[0m invalid syntax\n"
     ]
    }
   ],
   "source": [
    "eval('x = 5')\n",
    "\n",
    "#Resposta 2: O motivo da função acima apresentar o erro é devido ao fato de que o sinal de igual \"=\" não é um operador, mas sim um atribuidor.\n",
    "#Logo, assim é apresentado como um erro de sintaxe.\n"
   ]
  }
 ],
 "metadata": {
  "kernelspec": {
   "display_name": "Python 3",
   "language": "python",
   "name": "python3"
  },
  "language_info": {
   "codemirror_mode": {
    "name": "ipython",
    "version": 3
   },
   "file_extension": ".py",
   "mimetype": "text/x-python",
   "name": "python",
   "nbconvert_exporter": "python",
   "pygments_lexer": "ipython3",
   "version": "3.10.4"
  },
  "orig_nbformat": 4
 },
 "nbformat": 4,
 "nbformat_minor": 2
}
